{
 "cells": [
  {
   "cell_type": "code",
   "execution_count": 35,
   "metadata": {},
   "outputs": [
    {
     "name": "stderr",
     "output_type": "stream",
     "text": [
      "2677.60s - pydevd: Sending message related to process being replaced timed-out after 5 seconds\n"
     ]
    },
    {
     "name": "stdout",
     "output_type": "stream",
     "text": [
      "Requirement already satisfied: requests in /Library/Frameworks/Python.framework/Versions/3.8/lib/python3.8/site-packages (2.31.0)\n",
      "Requirement already satisfied: urllib3<3,>=1.21.1 in /Library/Frameworks/Python.framework/Versions/3.8/lib/python3.8/site-packages (from requests) (2.0.3)\n",
      "Requirement already satisfied: certifi>=2017.4.17 in /Library/Frameworks/Python.framework/Versions/3.8/lib/python3.8/site-packages (from requests) (2020.4.5.1)\n",
      "Requirement already satisfied: charset-normalizer<4,>=2 in /Library/Frameworks/Python.framework/Versions/3.8/lib/python3.8/site-packages (from requests) (3.2.0)\n",
      "Requirement already satisfied: idna<4,>=2.5 in /Library/Frameworks/Python.framework/Versions/3.8/lib/python3.8/site-packages (from requests) (3.4)\n",
      "\u001b[33mWARNING: You are using pip version 19.2.3, however version 23.2.1 is available.\n",
      "You should consider upgrading via the 'pip install --upgrade pip' command.\u001b[0m\n",
      "Note: you may need to restart the kernel to use updated packages.\n"
     ]
    }
   ],
   "source": [
    "%pip install requests"
   ]
  },
  {
   "cell_type": "code",
   "execution_count": 36,
   "metadata": {},
   "outputs": [
    {
     "name": "stderr",
     "output_type": "stream",
     "text": [
      "2684.13s - pydevd: Sending message related to process being replaced timed-out after 5 seconds\n"
     ]
    },
    {
     "name": "stdout",
     "output_type": "stream",
     "text": [
      "Requirement already satisfied: openai in /Library/Frameworks/Python.framework/Versions/3.8/lib/python3.8/site-packages (0.27.8)\n",
      "Requirement already satisfied: aiohttp in /Library/Frameworks/Python.framework/Versions/3.8/lib/python3.8/site-packages (from openai) (3.8.4)\n",
      "Requirement already satisfied: tqdm in /Library/Frameworks/Python.framework/Versions/3.8/lib/python3.8/site-packages (from openai) (4.65.0)\n",
      "Requirement already satisfied: requests>=2.20 in /Library/Frameworks/Python.framework/Versions/3.8/lib/python3.8/site-packages (from openai) (2.31.0)\n",
      "Requirement already satisfied: aiosignal>=1.1.2 in /Library/Frameworks/Python.framework/Versions/3.8/lib/python3.8/site-packages (from aiohttp->openai) (1.3.1)\n",
      "Requirement already satisfied: frozenlist>=1.1.1 in /Library/Frameworks/Python.framework/Versions/3.8/lib/python3.8/site-packages (from aiohttp->openai) (1.4.0)\n",
      "Requirement already satisfied: charset-normalizer<4.0,>=2.0 in /Library/Frameworks/Python.framework/Versions/3.8/lib/python3.8/site-packages (from aiohttp->openai) (3.2.0)\n",
      "Requirement already satisfied: attrs>=17.3.0 in /Library/Frameworks/Python.framework/Versions/3.8/lib/python3.8/site-packages (from aiohttp->openai) (23.1.0)\n",
      "Requirement already satisfied: async-timeout<5.0,>=4.0.0a3 in /Library/Frameworks/Python.framework/Versions/3.8/lib/python3.8/site-packages (from aiohttp->openai) (4.0.2)\n",
      "Requirement already satisfied: yarl<2.0,>=1.0 in /Library/Frameworks/Python.framework/Versions/3.8/lib/python3.8/site-packages (from aiohttp->openai) (1.9.2)\n",
      "Requirement already satisfied: multidict<7.0,>=4.5 in /Library/Frameworks/Python.framework/Versions/3.8/lib/python3.8/site-packages (from aiohttp->openai) (6.0.4)\n",
      "Requirement already satisfied: urllib3<3,>=1.21.1 in /Library/Frameworks/Python.framework/Versions/3.8/lib/python3.8/site-packages (from requests>=2.20->openai) (2.0.3)\n",
      "Requirement already satisfied: certifi>=2017.4.17 in /Library/Frameworks/Python.framework/Versions/3.8/lib/python3.8/site-packages (from requests>=2.20->openai) (2020.4.5.1)\n",
      "Requirement already satisfied: idna<4,>=2.5 in /Library/Frameworks/Python.framework/Versions/3.8/lib/python3.8/site-packages (from requests>=2.20->openai) (3.4)\n",
      "\u001b[33mWARNING: You are using pip version 19.2.3, however version 23.2.1 is available.\n",
      "You should consider upgrading via the 'pip install --upgrade pip' command.\u001b[0m\n",
      "Note: you may need to restart the kernel to use updated packages.\n"
     ]
    }
   ],
   "source": [
    "%pip install openai"
   ]
  },
  {
   "cell_type": "code",
   "execution_count": 37,
   "metadata": {},
   "outputs": [
    {
     "ename": "HTTPError",
     "evalue": "401 Client Error: Unauthorized for url: https://api.openai.com/v1/engines/davinci/completions",
     "output_type": "error",
     "traceback": [
      "\u001b[0;31m---------------------------------------------------------------------------\u001b[0m",
      "\u001b[0;31mHTTPError\u001b[0m                                 Traceback (most recent call last)",
      "Cell \u001b[0;32mIn[37], line 33\u001b[0m\n\u001b[1;32m     30\u001b[0m prompt \u001b[39m=\u001b[39m \u001b[39m\"\u001b[39m\u001b[39mOnce upon a time in a galaxy far, far away...\u001b[39m\u001b[39m\"\u001b[39m\n\u001b[1;32m     32\u001b[0m \u001b[39m# Call the GPT-3 API\u001b[39;00m\n\u001b[0;32m---> 33\u001b[0m response_text \u001b[39m=\u001b[39m call_gpt3(prompt)\n\u001b[1;32m     35\u001b[0m \u001b[39m# Print the response\u001b[39;00m\n\u001b[1;32m     36\u001b[0m \u001b[39mprint\u001b[39m(response_text)\n",
      "Cell \u001b[0;32mIn[37], line 26\u001b[0m, in \u001b[0;36mcall_gpt3\u001b[0;34m(prompt)\u001b[0m\n\u001b[1;32m     19\u001b[0m data \u001b[39m=\u001b[39m {\n\u001b[1;32m     20\u001b[0m     \u001b[39m\"\u001b[39m\u001b[39mprompt\u001b[39m\u001b[39m\"\u001b[39m: prompt,\n\u001b[1;32m     21\u001b[0m     \u001b[39m\"\u001b[39m\u001b[39mtemperature\u001b[39m\u001b[39m\"\u001b[39m: \u001b[39m0.7\u001b[39m,\n\u001b[1;32m     22\u001b[0m     \u001b[39m\"\u001b[39m\u001b[39mmax_tokens\u001b[39m\u001b[39m\"\u001b[39m: \u001b[39m150\u001b[39m,\n\u001b[1;32m     23\u001b[0m     \u001b[39m\"\u001b[39m\u001b[39mstop\u001b[39m\u001b[39m\"\u001b[39m: \u001b[39m\"\u001b[39m\u001b[39m\\n\u001b[39;00m\u001b[39m\"\u001b[39m\n\u001b[1;32m     24\u001b[0m }\n\u001b[1;32m     25\u001b[0m response \u001b[39m=\u001b[39m requests\u001b[39m.\u001b[39mpost(url, headers\u001b[39m=\u001b[39mheaders, json\u001b[39m=\u001b[39mdata)\n\u001b[0;32m---> 26\u001b[0m response\u001b[39m.\u001b[39;49mraise_for_status()  \u001b[39m# Check for any errors in the response\u001b[39;00m\n\u001b[1;32m     27\u001b[0m \u001b[39mreturn\u001b[39;00m response\u001b[39m.\u001b[39mjson()[\u001b[39m\"\u001b[39m\u001b[39mchoices\u001b[39m\u001b[39m\"\u001b[39m][\u001b[39m0\u001b[39m][\u001b[39m\"\u001b[39m\u001b[39mtext\u001b[39m\u001b[39m\"\u001b[39m]\n",
      "File \u001b[0;32m/Library/Frameworks/Python.framework/Versions/3.8/lib/python3.8/site-packages/requests/models.py:1021\u001b[0m, in \u001b[0;36mResponse.raise_for_status\u001b[0;34m(self)\u001b[0m\n\u001b[1;32m   1016\u001b[0m     http_error_msg \u001b[39m=\u001b[39m (\n\u001b[1;32m   1017\u001b[0m         \u001b[39mf\u001b[39m\u001b[39m\"\u001b[39m\u001b[39m{\u001b[39;00m\u001b[39mself\u001b[39m\u001b[39m.\u001b[39mstatus_code\u001b[39m}\u001b[39;00m\u001b[39m Server Error: \u001b[39m\u001b[39m{\u001b[39;00mreason\u001b[39m}\u001b[39;00m\u001b[39m for url: \u001b[39m\u001b[39m{\u001b[39;00m\u001b[39mself\u001b[39m\u001b[39m.\u001b[39murl\u001b[39m}\u001b[39;00m\u001b[39m\"\u001b[39m\n\u001b[1;32m   1018\u001b[0m     )\n\u001b[1;32m   1020\u001b[0m \u001b[39mif\u001b[39;00m http_error_msg:\n\u001b[0;32m-> 1021\u001b[0m     \u001b[39mraise\u001b[39;00m HTTPError(http_error_msg, response\u001b[39m=\u001b[39m\u001b[39mself\u001b[39m)\n",
      "\u001b[0;31mHTTPError\u001b[0m: 401 Client Error: Unauthorized for url: https://api.openai.com/v1/engines/davinci/completions"
     ]
    }
   ],
   "source": [
    "import openai\n",
    "import os\n",
    "import requests\n",
    "from dotenv import load_dotenv\n",
    "\n",
    "# Load environment variables from .env\n",
    "load_dotenv()\n",
    "\n",
    "# Get the API key from the environment variables\n",
    "api_key = os.getenv(\"API_KEY\")\n",
    "\n",
    "# Function to interact with the GPT-3.5 API\n",
    "def call_gpt3(prompt):\n",
    "    url = \"https://api.openai.com/v1/engines/davinci/completions\"\n",
    "    headers = {\n",
    "        \"Content-Type\": \"application/json\",\n",
    "        \"Authorization\": f\"Bearer {api_key}\"\n",
    "    }\n",
    "    data = {\n",
    "        \"prompt\": prompt,\n",
    "        \"temperature\": 0.7,\n",
    "        \"max_tokens\": 150,\n",
    "        \"stop\": \"\\n\"\n",
    "    }\n",
    "    response = requests.post(url, headers=headers, json=data)\n",
    "    response.raise_for_status()  # Check for any errors in the response\n",
    "    return response.json()[\"choices\"][0][\"text\"]\n",
    "\n",
    "# Set your prompt for GPT-3\n",
    "prompt = \"Once upon a time in a galaxy far, far away...\"\n",
    "\n",
    "# Call the GPT-3 API\n",
    "response_text = call_gpt3(prompt)\n",
    "\n",
    "# Print the response\n",
    "print(response_text)\n"
   ]
  },
  {
   "cell_type": "code",
   "execution_count": null,
   "metadata": {},
   "outputs": [],
   "source": []
  }
 ],
 "metadata": {
  "kernelspec": {
   "display_name": "Python 3",
   "language": "python",
   "name": "python3"
  },
  "language_info": {
   "codemirror_mode": {
    "name": "ipython",
    "version": 3
   },
   "file_extension": ".py",
   "mimetype": "text/x-python",
   "name": "python",
   "nbconvert_exporter": "python",
   "pygments_lexer": "ipython3",
   "version": "3.8.3rc1"
  },
  "orig_nbformat": 4
 },
 "nbformat": 4,
 "nbformat_minor": 2
}
